Workbook

Sheet Historical Stock Data
A1: GP Data | D1: DSEX Data
A2: Date | B2: Price | D2: Date | E2: Price
A3: 45988 | B3: 278.4 | D3: 45988 | E3: 5028.14
A4: 45987 | B4: 277.9 | D4: 45987 | E4: 5009.8
A5: 45986 | B5: 277.5 | D5: 45986 | E5: 5018.28
A6: 45985 | B6: 275.2 | D6: 45985 | E6: 5024.86
A7: 45984 | B7: 274 | D7: 45984 | E7: 4915.75
A8: 45981 | B8: 273.3 | D8: 45981 | E8: 4869.01
A9: 45980 | B9: 273.9 | D9: 45980 | E9: 4901.38
A10: 45979 | B10: 272.4 | D10: 45979 | E10: 4846.88
A11: 45978 | B11: 271.9 | D11: 45978 | E11: 4774.96
A12: 45977 | B12: 271.4 | D12: 45977 | E12: 4732.16
A13: 45974 | B13: 277.2 | D13: 45974 | E13: 4702.69
A14: 45973 | B14: 278.5 | D14: 45973 | E14: 4825.33
... A1530: 43599 | B1530: 346.6 | D1530: 43431 | E1530: 5288.54
A1531: 43598 | B1531: 348.1
A1532: 43597 | B1532: 352.4
A1533: 43594 | B1533: 354.1
A1534: 43593 | B1534: 354.6
A1535: 43592 | B1535: 354.4
A1536: 43591 | B1536: 359.4
A1537: 43590 | B1537: 362.5
A1538: 43587 | B1538: 358.2
A1539: 43585 | B1539: 358.7
A1540: 43584 | B1540: 360
A1541: 43583 | B1541: 365.2
A1542: 43580 | B1542: 364.2
... A1639: 43431 | B1639: 366

Sheet Return Calculations
A1: GP | E1: DSEX | J1: GP Return | K1: DSEX Return | M1: Starting Date | N1: 43431 | R1: STEPS
A2: Date | B2: Price | C2: Return | E2: Date | F2: Price | G2: Return | J2: =(B3/B4)-1 -> 0.0017992083 | K2: =(F3/F4)-1 -> 0.0036608248 | M2: Ending Date | N2: =A3 -> 45988 | R2: 1 | S2: 1.Investing.com- Gp historical data 2.Investing.com- DSEX historical data 3. Remove uncommon dates using SQL 4. Calculate daily return using excel formula 5. Remove 0 returns (33, 0 returns in total)
A3: 45988 | B3: =VLOOKUP(A3,'[2]GP Data'!$A$3:$B$1639, 2, FALSE) -> 278.4 | C3: =(B3/B4)-1 -> 0.0017992083 | E3: 45988 | F3: =VLOOKUP(E3,'[2]GP Data'!$D$3:$E$1530, 2, FALSE) -> 5028.14 | G3: =(F3/F4)-1 -> 0.0036608248 | J3: =(B4/B5)-1 -> 0.0014414414 | K3: =(F4/F5)-1 -> -0.001689822 | M3: Range | N3: 7 Years
A4: 45987 | B4: 277.9 | C4: =(B4/B5)-1 -> 0.0014414414 | E4: 45987 | F4: =VLOOKUP(E4,'[2]GP Data'!$D$3:$E$1530, 2, FALSE) -> 5009.8 | G4: =(F4/F5)-1 -> -0.001689822 | J4: =(B5/B6)-1 -> 0.0083575581 | K4: =(F5/F6)-1 -> -0.0013094892
A5: 45986 | B5: =VLOOKUP(A5,'[2]GP Data'!$A$3:$B$1639, 2, FALSE) -> 277.5 | C5: =(B5/B6)-1 -> 0.0083575581 | E5: 45986 | F5: =VLOOKUP(E5,'[2]GP Data'!$D$3:$E$1530, 2, FALSE) -> 5018.28 | G5: =(F5/F6)-1 -> -0.0013094892 | J5: =(B6/B7)-1 -> 0.004379562 | K5: =(F6/F7)-1 -> 0.022196003 | M5: SLOPE | N5: =SLOPE(J2:J1188,K2:K1188) -> 0.85102811
A6: 45985 | B6: =VLOOKUP(A6,'[2]GP Data'!$A$3:$B$1639, 2, FALSE) -> 275.2 | C6: =(B6/B7)-1 -> 0.004379562 | E6: 45985 | F6: =VLOOKUP(E6,'[2]GP Data'!$D$3:$E$1530, 2, FALSE) -> 5024.86 | G6: =(F6/F7)-1 -> 0.022196003 | J6: =(B7/B8)-1 -> 0.002561288 | K6: =(F7/F8)-1 -> 0.0095994874 | M6: R-SQUARE | N6: =RSQ(K2:K1188,J2:J1188) -> 0.29126945 | R6: 2 | S6: GP Return and DSE Return over the 7 years has been used to conjure a scatter plot, comparing the impact of GP return changes due to market fluctuations. The linear equation and R square value has been shown. GP return is y value (dependant variable) and DSEX Return is x variable (Independant variable). The slope value of 0.851 is the beta of GP.
A7: 45984 | B7: =VLOOKUP(A7,'[2]GP Data'!$A$3:$B$1639, 2, FALSE) -> 274 | C7: =(B7/B8)-1 -> 0.002561288 | E7: 45984 | F7: =VLOOKUP(E7,'[2]GP Data'!$D$3:$E$1530, 2, FALSE) -> 4915.75 | G7: =(F7/F8)-1 -> 0.0095994874 | J7: =(B8/B9)-1 -> -0.0021905805 | K7: =(F8/F9)-1 -> -0.0066042625 | M7: ALPHA | N7: =INTERCEPT(K2:K1188,J2:J1188) -> 4.45452e-05
A8: 45981 | B8: =VLOOKUP(A8,'[2]GP Data'!$A$3:$B$1639, 2, FALSE) -> 273.3 | C8: =(B8/B9)-1 -> -0.0021905805 | E8: 45981 | F8: =VLOOKUP(E8,'[2]GP Data'!$D$3:$E$1530, 2, FALSE) -> 4869.01 | G8: =(F8/F9)-1 -> -0.0066042625 | J8: =(B9/B10)-1 -> 0.0055066079 | K8: =(F9/F10)-1 -> 0.011244347
A9: 45980 | B9: =VLOOKUP(A9,'[2]GP Data'!$A$3:$B$1639, 2, FALSE) -> 273.9 | C9: =(B9/B10)-1 -> 0.0055066079 | E9: 45980 | F9: =VLOOKUP(E9,'[2]GP Data'!$D$3:$E$1530, 2, FALSE) -> 4901.38 | G9: =(F9/F10)-1 -> 0.011244347 | J9: =(B10/B11)-1 -> 0.0018389114 | K9: =(F10/F11)-1 -> 0.015061906
A10: 45979 | B10: =VLOOKUP(A10,'[2]GP Data'!$A$3:$B$1639, 2, FALSE) -> 272.4 | C10: =(B10/B11)-1 -> 0.0018389114 | E10: 45979 | F10: =VLOOKUP(E10,'[2]GP Data'!$D$3:$E$1530, 2, FALSE) -> 4846.88 | G10: =(F10/F11)-1 -> 0.015061906 | J10: =(B11/B12)-1 -> 0.0018422992 | K10: =(F11/F12)-1 -> 0.0090444955
A11: 45978 | B11: =VLOOKUP(A11,'[2]GP Data'!$A$3:$B$1639, 2, FALSE) -> 271.9 | C11: =(B11/B12)-1 -> 0.0018422992 | E11: 45978 | F11: =VLOOKUP(E11,'[2]GP Data'!$D$3:$E$1530, 2, FALSE) -> 4774.96 | G11: =(F11/F12)-1 -> 0.0090444955 | J11: =(B12/B13)-1 -> -0.020923521 | K11: =(F12/F13)-1 -> 0.0062666261
A12: 45977 | B12: =VLOOKUP(A12,'[2]GP Data'!$A$3:$B$1639, 2, FALSE) -> 271.4 | C12: =(B12/B13)-1 -> -0.020923521 | E12: 45977 | F12: =VLOOKUP(E12,'[2]GP Data'!$D$3:$E$1530, 2, FALSE) -> 4732.16 | G12: =(F12/F13)-1 -> 0.0062666261 | J12: =(B13/B14)-1 -> -0.0046678636 | K12: =(F13/F14)-1 -> -0.025415878
A13: 45974 | B13: =VLOOKUP(A13,'[2]GP Data'!$A$3:$B$1639, 2, FALSE) -> 277.2 | C13: =(B13/B14)-1 -> -0.0046678636 | E13: 45974 | F13: =VLOOKUP(E13,'[2]GP Data'!$D$3:$E$1530, 2, FALSE) -> 4702.69 | G13: =(F13/F14)-1 -> -0.025415878 | J13: =(B14/B15)-1 -> 0.0028808066 | K13: =(F14/F15)-1 -> -0.0097357355
A14: 45973 | B14: =VLOOKUP(A14,'[2]GP Data'!$A$3:$B$1639, 2, FALSE) -> 278.5 | C14: =(B14/B15)-1 -> 0.0028808066 | E14: 45973 | F14: =VLOOKUP(E14,'[2]GP Data'!$D$3:$E$1530, 2, FALSE) -> 4825.33 | G14: =(F14/F15)-1 -> -0.0097357355 | J14: =(B15/B16)-1 -> 0.0014424811 | K14: =(F15/F16)-1 -> 0.0024728694
A15: 45972 | B15: =VLOOKUP(A15,'[2]GP Data'!$A$3:$B$1639, 2, FALSE) -> 277.7 | C15: =(B15/B16)-1 -> 0.0014424811 | E15: 45972 | F15: =VLOOKUP(E15,'[2]GP Data'!$D$3:$E$1530, 2, FALSE) -> 4872.77 | G15: =(F15/F16)-1 -> 0.0024728694 | J15: =(B16/B17)-1 -> -0.013518321 | K15: =(F16/F17)-1 -> -0.0079960326
A16: 45971 | B16: =VLOOKUP(A16,'[2]GP Data'!$A$3:$B$1639, 2, FALSE) -> 277.3 | C16: =(B16/B17)-1 -> -0.013518321 | E16: 45971 | F16: =VLOOKUP(E16,'[2]GP Data'!$D$3:$E$1530, 2, FALSE) -> 4860.75 | G16: =(F16/F17)-1 -> -0.0079960326 | J16: =(B17/B18)-1 -> -0.0060113154 | K16: =(F17/F18)-1 -> -0.013689779
A17: 45970 | B17: =VLOOKUP(A17,'[2]GP Data'!$A$3:$B$1639, 2, FALSE) -> 281.1 | C17: =(B17/B18)-1 -> -0.0060113154 | E17: 45970 | F17: =VLOOKUP(E17,'[2]GP Data'!$D$3:$E$1530, 2, FALSE) -> 4899.93 | G17: =(F17/F18)-1 -> -0.013689779 | J17: =(B18/B19)-1 -> -0.0052761168 | K17: =(F18/F19)-1 -> -0.0037999635
A18: 45967 | B18: =VLOOKUP(A18,'[2]GP Data'!$A$3:$B$1639, 2, FALSE) -> 282.8 | C18: =(B18/B19)-1 -> -0.0052761168 | E18: 45967 | F18: =VLOOKUP(E18,'[2]GP Data'!$D$3:$E$1530, 2, FALSE) -> 4967.94 | G18: =(F18/F19)-1 -> -0.0037999635 | J18: =(B19/B20)-1 -> 0.003529827 | K18: =(F19/F20)-1 -> -0.0064115464
A19: 45966 | B19: =VLOOKUP(A19,'[2]GP Data'!$A$3:$B$1639, 2, FALSE) -> 284.3 | C19: =(B19/B20)-1 -> 0.003529827 | E19: 45966 | F19: =VLOOKUP(E19,'[2]GP Data'!$D$3:$E$1530, 2, FALSE) -> 4986.89 | G19: =(F19/F20)-1 -> -0.0064115464 | J19: =(B20/B21)-1 -> 0.0078263963 | K19: =(F20/F21)-1 -> -0.0082868834
... A35: 45944 | B35: =VLOOKUP(A35,'[2]GP Data'!$A$3:$B$1639, 2, FALSE) -> 292.4 | C35: =(B35/B36)-1 -> -0.0054421769 | E35: 45944 | F35: =VLOOKUP(E35,'[2]GP Data'!$D$3:$E$1530, 2, FALSE) -> 5197.27 | G35: =(F35/F36)-1 -> -0.0058304242 | J35: =(B36/B37)-1 -> 0.0017035775 | K35: =(F36/F37)-1 -> 0.0048611618
A36: 45943 | B36: =VLOOKUP(A36,'[2]GP Data'!$A$3:$B$1639, 2, FALSE) -> 294 | C36: =(B36/B37)-1 -> 0.0017035775 | E36: 45943 | F36: =VLOOKUP(E36,'[2]GP Data'!$D$3:$E$1530, 2, FALSE) -> 5227.75 | G36: =(F36/F37)-1 -> 0.0048611618 | J36: =(B37/B38)-1 -> -0.0027183146 | K36: =(F37/F38)-1 -> -0.015379316 | M36: Beta | N36: Source | O36: Data Frame
A37: 45942 | B37: =VLOOKUP(A37,'[2]GP Data'!$A$3:$B$1639, 2, FALSE) -> 293.5 | C37: =(B37/B38)-1 -> -0.0027183146 | E37: 45942 | F37: =VLOOKUP(E37,'[2]GP Data'!$D$3:$E$1530, 2, FALSE) -> 5202.46 | G37: =(F37/F38)-1 -> -0.015379316 | J37: =(B38/B39)-1 -> 0.00033990483 | K37: =(F38/F39)-1 -> -0.010142641 | M37: 0.48 | N37: https://www.amarstock.com/stock/GP | O37: 10 - 15 years
A38: 45939 | B38: =VLOOKUP(A38,'[2]GP Data'!$A$3:$B$1639, 2, FALSE) -> 294.3 | C38: =(B38/B39)-1 -> 0.00033990483 | E38: 45939 | F38: =VLOOKUP(E38,'[2]GP Data'!$D$3:$E$1530, 2, FALSE) -> 5283.72 | G38: =(F38/F39)-1 -> -0.010142641 | J38: =(B39/B40)-1 -> -0.0016966407 | K38: =(F39/F40)-1 -> -0.0072791519 | M38: 0.98 | N38: https://biniyog.com.bd/company/gp
A39: 45938 | B39: =VLOOKUP(A39,'[2]GP Data'!$A$3:$B$1639, 2, FALSE) -> 294.2 | C39: =(B39/B40)-1 -> -0.0016966407 | E39: 45938 | F39: =VLOOKUP(E39,'[2]GP Data'!$D$3:$E$1530, 2, FALSE) -> 5337.86 | G39: =(F39/F40)-1 -> -0.0072791519 | J39: =(B40/B41)-1 -> -0.011405569 | K39: =(F40/F41)-1 -> -0.0085993908 | M39: 0.7 | N39: https://dspace.bracu.ac.bd:8443/xmlui/bitstream/handle/10361/18020/17104210_BBA.pdf?sequence=1&isAllowed=y | O39: 2016 - 2020
A40: 45937 | B40: =VLOOKUP(A40,'[2]GP Data'!$A$3:$B$1639, 2, FALSE) -> 294.7 | C40: =(B40/B41)-1 -> -0.011405569 | E40: 45937 | F40: =VLOOKUP(E40,'[2]GP Data'!$D$3:$E$1530, 2, FALSE) -> 5377 | G40: =(F40/F41)-1 -> -0.0085993908 | J40: =(B41/B42)-1 -> -0.0020087044 | K40: =(F41/F42)-1 -> -0.0044037499 | M40: 0.13 | N40: https://www.investing.com/pro/DSE:GP/explorer/beta | O40: 5 years
A41: 45936 | B41: =VLOOKUP(A41,'[2]GP Data'!$A$3:$B$1639, 2, FALSE) -> 298.1 | C41: =(B41/B42)-1 -> -0.0020087044 | E41: 45936 | F41: =VLOOKUP(E41,'[2]GP Data'!$D$3:$E$1530, 2, FALSE) -> 5423.64 | G41: =(F41/F42)-1 -> -0.0044037499 | J41: =(B42/B43)-1 -> -0.0010033445 | K41: =(F42/F43)-1 -> 0.0058791054
A42: 45935 | B42: =VLOOKUP(A42,'[2]GP Data'!$A$3:$B$1639, 2, FALSE) -> 298.7 | C42: =(B42/B43)-1 -> -0.0010033445 | E42: 45935 | F42: =VLOOKUP(E42,'[2]GP Data'!$D$3:$E$1530, 2, FALSE) -> 5447.63 | G42: =(F42/F43)-1 -> 0.0058791054 | J42: =(B43/B44)-1 -> 0.0033557047 | K42: =(F43/F44)-1 -> 0.0048257999
A43: 45930 | B43: =VLOOKUP(A43,'[2]GP Data'!$A$3:$B$1639, 2, FALSE) -> 299 | C43: =(B43/B44)-1 -> 0.0033557047 | E43: 45930 | F43: =VLOOKUP(E43,'[2]GP Data'!$D$3:$E$1530, 2, FALSE) -> 5415.79 | G43: =(F43/F44)-1 -> 0.0048257999 | J43: =(B44/B45)-1 -> -0.0036776998 | K43: =(F44/F45)-1 -> 0.0018029472
A44: 45929 | B44: =VLOOKUP(A44,'[2]GP Data'!$A$3:$B$1639, 2, FALSE) -> 298 | C44: =(B44/B45)-1 -> -0.0036776998 | E44: 45929 | F44: =VLOOKUP(E44,'[2]GP Data'!$D$3:$E$1530, 2, FALSE) -> 5389.78 | G44: =(F44/F45)-1 -> 0.0018029472 | J44: =(B45/B46)-1 -> 0.0023458445 | K44: =(F45/F46)-1 -> -0.0064726055
A45: 45928 | B45: =VLOOKUP(A45,'[2]GP Data'!$A$3:$B$1639, 2, FALSE) -> 299.1 | C45: =(B45/B46)-1 -> 0.0023458445 | E45: 45928 | F45: =VLOOKUP(E45,'[2]GP Data'!$D$3:$E$1530, 2, FALSE) -> 5380.08 | G45: =(F45/F46)-1 -> -0.0064726055 | J45: =(B46/B47)-1 -> -0.002006689 | K45: =(F46/F47)-1 -> 0.0041686369
A46: 45925 | B46: =VLOOKUP(A46,'[2]GP Data'!$A$3:$B$1639, 2, FALSE) -> 298.4 | C46: =(B46/B47)-1 -> -0.002006689 | E46: 45925 | F46: =VLOOKUP(E46,'[2]GP Data'!$D$3:$E$1530, 2, FALSE) -> 5415.13 | G46: =(F46/F47)-1 -> 0.0041686369 | J46: =(B47/B48)-1 -> 0.0016750419 | K46: =(F47/F48)-1 -> 0.0084488553
A47: 45924 | B47: =VLOOKUP(A47,'[2]GP Data'!$A$3:$B$1639, 2, FALSE) -> 299 | C47: =(B47/B48)-1 -> 0.0016750419 | E47: 45924 | F47: =VLOOKUP(E47,'[2]GP Data'!$D$3:$E$1530, 2, FALSE) -> 5392.65 | G47: =(F47/F48)-1 -> 0.0084488553 | J47: =(B48/B49)-1 -> -0.0053315561 | K47: =(F48/F49)-1 -> 0.0019354935
A48: 45923 | B48: =VLOOKUP(A48,'[2]GP Data'!$A$3:$B$1639, 2, FALSE) -> 298.5 | C48: =(B48/B49)-1 -> -0.0053315561 | E48: 45923 | F48: =VLOOKUP(E48,'[2]GP Data'!$D$3:$E$1530, 2, FALSE) -> 5347.47 | G48: =(F48/F49)-1 -> 0.0019354935 | J48: =(B49/B50)-1 -> -0.00066600067 | K48: =(F49/F50)-1 -> -0.0083075522
A49: 45922 | B49: =VLOOKUP(A49,'[2]GP Data'!$A$3:$B$1639, 2, FALSE) -> 300.1 | C49: =(B49/B50)-1 -> -0.00066600067 | E49: 45922 | F49: =VLOOKUP(E49,'[2]GP Data'!$D$3:$E$1530, 2, FALSE) -> 5337.14 | G49: =(F49/F50)-1 -> -0.0083075522 | J49: =(B50/B51)-1 -> -0.0026569246 | K49: =(F50/F51)-1 -> -0.012491904
A50: 45921 | B50: =VLOOKUP(A50,'[2]GP Data'!$A$3:$B$1639, 2, FALSE) -> 300.3 | C50: =(B50/B51)-1 -> -0.0026569246 | E50: 45921 | F50: =VLOOKUP(E50,'[2]GP Data'!$D$3:$E$1530, 2, FALSE) -> 5381.85 | G50: =(F50/F51)-1 -> -0.012491904 | J50: =(B51/B52)-1 -> -0.0023194168 | K50: =(F51/F52)-1 -> -0.010831983
A51: 45918 | B51: =VLOOKUP(A51,'[2]GP Data'!$A$3:$B$1639, 2, FALSE) -> 301.1 | C51: =(B51/B52)-1 -> -0.0023194168 | E51: 45918 | F51: =VLOOKUP(E51,'[2]GP Data'!$D$3:$E$1530, 2, FALSE) -> 5449.93 | G51: =(F51/F52)-1 -> -0.010831983 | J51: =(B52/B53)-1 -> 0.0026578073 | K51: =(F52/F53)-1 -> 0.0063729287
A52: 45916 | B52: =VLOOKUP(A52,'[2]GP Data'!$A$3:$B$1639, 2, FALSE) -> 301.8 | C52: =(B52/B53)-1 -> 0.0026578073 | E52: 45916 | F52: =VLOOKUP(E52,'[2]GP Data'!$D$3:$E$1530, 2, FALSE) -> 5509.61 | G52: =(F52/F53)-1 -> 0.0063729287 | J52: =(B53/B54)-1 -> 0.0036678893 | K52: =(F53/F54)-1 -> 0.0011648852
... A65: 45897 | B65: =VLOOKUP(A65,'[2]GP Data'!$A$3:$B$1639, 2, FALSE) -> 305.4 | C65: =(B65/B66)-1 -> 0.02277294 | E65: 45897 | F65: =VLOOKUP(E65,'[2]GP Data'!$D$3:$E$1530, 2, FALSE) -> 5517.95 | G65: =(F65/F66)-1 -> 0.012685292 | J65: =(B66/B67)-1 -> -0.00033478406 | K65: =(F66/F67)-1 -> -0.0012043113
A66: 45895 | B66: =VLOOKUP(A66,'[2]GP Data'!$A$3:$B$1639, 2, FALSE) -> 298.6 | C66: =(B66/B67)-1 -> -0.00033478406 | E66: 45895 | F66: 5448.83 | G66: =(F66/F67)-1 -> -0.0012043113 | J66: =(B67/B68)-1 -> 0.0070802428 | K66: =(F67/F68)-1 -> 0.012289462
A67: 45894 | B67: =VLOOKUP(A67,'[2]GP Data'!$A$3:$B$1639, 2, FALSE) -> 298.7 | C67: =(B67/B68)-1 -> 0.0070802428 | E67: 45894 | F67: =VLOOKUP(E67,'[2]GP Data'!$D$3:$E$1530, 2, FALSE) -> 5455.4 | G67: =(F67/F68)-1 -> 0.012289462 | J67: =(B68/B69)-1 -> -0.0086898396 | K67: =(F68/F69)-1 -> 0.0026437406
...

Sheet CAPM
A1: Using DSEX/DGEN | F1: Using Market Capitalization | Q1: Step 01: Over here, I took 20 years worth of ending price from DSEX Index (Investing.com). Discrete return method has been used to find the changes through the years. To adjust for the final average of all these rates, the return rates were added with 1 (Geomean function will be used for averaging these rates).
A2: Year | B2: Index | C2: Return | F2: Year | G2: Market cap (Tk Crore) | H2: Return | I2: GEO Mean Adjusted
A3: 2005 | B3: 1630.91 | F3: 2005 | G3: 222000
A4: 2006 | B4: 1564.94 | C4: =(B4/B3)-1 -> -0.04044981 | D4: =C4+1 -> 0.95955019 | F4: 2006 | G4: 323368 | H4: =(G4/G3)-1 -> 0.45661261 | I4: =H4+1 -> 1.4566126
A5: 2007 | B5: 2933.67 | C5: =(B5/B4)-1 -> 0.87462139 | D5: =C5+1 -> 1.8746214 | F5: 2007 | G5: 753955 | H5: =(G5/G4)-1 -> 1.3315696 | I5: =H5+1 -> 2.3315696 | L5: Cost of Equity (via CAPM) | Q5: Step 02:As BD market is very volatile, hence market cap data will be used for 20 years. The data has been collected from BSEC Annual reports over the years. The same step repeated as step 1, just average of 20 years and 10 years data has been taken to keep consistency.
A6: 2008 | B6: 2717.94 | C6: =(B6/B5)-1 -> -0.073535878 | D6: =C6+1 -> 0.92646412 | F6: 2008 | G6: 1059530 | H6: =(G6/G5)-1 -> 0.40529607 | I6: =H6+1 -> 1.4052961 | L6: Market Return (Rm) | N6: =M14 -> 0.14200259
A7: 2009 | B7: 4409.94 | C7: =(B7/B6)-1 -> 0.6225303 | D7: =C7+1 -> 1.6225303 | F7: 2009 | G7: 1887177 | H7: =(G7/G6)-1 -> 0.78114541 | I7: =H7+1 -> 1.7811454 | L7: Risk free rate (Rf) | N7: =(0.09689+0.12)/2 -> 0.108445
A8: 2010 | B8: 8060.85 | C8: =(B8/B7)-1 -> 0.82788201 | D8: =C8+1 -> 1.827882 | F8: 2010 | G8: 3471109 | H8: =(G8/G7)-1 -> 0.8393129 | I8: =H8+1 -> 1.8393129 | L8: GP Beta | N8: ='[2]Return (Daily)'!N5 -> 0.85102811
A9: 2011 | B9: 5112.03 | C9: =(B9/B8)-1 -> -0.36581998 | D9: =C9+1 -> 0.63418002 | F9: 2011 | G9: 2327000 | H9: =(G9/G8)-1 -> -0.32960907 | I9: =H9+1 -> 0.67039093 | L9: CAPM (Ra) | N9: =N7+N8*(N6-N7) -> 0.13700346
A10: 2012 | B10: 4102.48 | C10: =(B10/B9)-1 -> -0.19748515 | D10: =C10+1 -> 0.80251485 | F10: 2012 | G10: 1933500 | H10: =(G10/G9)-1 -> -0.16910185 | I10: =H10+1 -> 0.83089815
A11: 2013 | B11: 4266.55 | C11: =(B11/B10)-1 -> 0.039992882 | D11: =C11+1 -> 1.0399929 | F11: 2013 | G11: 1977400 | H11: =(G11/G10)-1 -> 0.022704939 | I11: =H11+1 -> 1.0227049 | K11: Using DSEX Market capitalization data of 20 years (2005-2025) | Q11: Step 03: Over here, the market average has been found using Geomean function for 20 years of market cap data. The market return (Rm) is equal to the market cap average.
A12: 2014 | B12: 4864.96 | C12: =(B12/B11)-1 -> 0.14025618 | D12: =C12+1 -> 1.1402562 | F12: 2014 | G12: 2694448 | H12: =(G12/G11)-1 -> 0.36262162 | I12: =H12+1 -> 1.3626216 | K12: Market Return, Rm (whole period) | M12: =GEOMEAN(I3:I23)-1 -> 0.18549203
A13: 2015 | B13: 4629.64 | C13: =(B13/B12)-1 -> -0.048370387 | D13: =C13+1 -> 0.95162961 | F13: 2015 | G13: 2607793 | H13: =(G13/G12)-1 -> -0.032160576 | I13: =H13+1 -> 0.96783942 | K13: Market cap (last 10 years) | M13: =GEOMEAN(I14:I23)-1 -> 0.098513157
A14: 2016 | B14: 5036.05 | C14: =(B14/B13)-1 -> 0.087784363 | D14: =C14+1 -> 1.0877844 | F14: 2016 | G14: 3186000 | H14: =(G14/G13)-1 -> 0.22172274 | I14: =H14+1 -> 1.2217227 | K14: Average Rm | M14: =AVERAGE(M12,M13) -> 0.14200259
A15: 2017 | B15: 6244.52 | C15: =(B15/B14)-1 -> 0.23996386 | D15: =C15+1 -> 1.2399639 | F15: 2017 | G15: 3801000 | H15: =(G15/G14)-1 -> 0.19303202 | I15: =H15+1 -> 1.193032
A16: 2018 | B16: 5385.64 | C16: =(B16/B15)-1 -> -0.1375414 | D16: =C16+1 -> 0.8624586 | F16: 2018 | G16: 3847000 | H16: =(G16/G15)-1 -> 0.012102078 | I16: =H16+1 -> 1.0121021
A17: 2019 | B17: 4452.93 | C17: =(B17/B16)-1 -> -0.17318462 | D17: =C17+1 -> 0.82681538 | F17: 2019 | G17: 3998000 | H17: =(G17/G16)-1 -> 0.039251365 | I17: =H17+1 -> 1.0392514 | Q17: Step 4: Bangladesh Bank treasury bond data for 364 days is 9.69% to 12% which is the Rf rate. With the other information available, the cost of equity using the CAPM method has been found.
A18: 2020 | B18: 5402.07 | C18: =(B18/B17)-1 -> 0.21314954 | D18: =C18+1 -> 1.2131495 | F18: 2020 | G18: 3120000 | H18: =(G18/G17)-1 -> -0.2196098 | I18: =H18+1 -> 0.7803902
A19: 2021 | B19: 6756.66 | C19: =(B19/B18)-1 -> 0.25075388 | D19: =C19+1 -> 1.2507539 | F19: 2021 | G19: 5142800 | H19: =(G19/G18)-1 -> 0.64833333 | I19: =H19+1 -> 1.6483333
A20: 2022 | B20: 6206.81 | C20: =(B20/B19)-1 -> -0.081378965 | D20: =C20+1 -> 0.91862103 | F20: 2022 | G20: 5177816 | H20: =(G20/G19)-1 -> 0.0068087423 | I20: =H20+1 -> 1.0068087
A21: 2023 | B21: 6246.5 | C21: =(B21/B20)-1 -> 0.0063945892 | D21: =C21+1 -> 1.0063946 | F21: 2023 | G21: 7720780 | H21: =(G21/G20)-1 -> 0.49112676 | I21: =H21+1 -> 1.4911268
A22: 2024 | B22: 5216.44 | C22: =(B22/B21)-1 -> -0.16490195 | D22: =C22+1 -> 0.83509805 | F22: 2024 | G22: 6621673 | H22: =(G22/G21)-1 -> -0.14235699 | I22: =H22+1 -> 0.85764301
A23: 2025 | B23: 4914.72 | C23: =(B23/B22)-1 -> -0.057840213 | D23: =C23+1 -> 0.94215979 | F23: 2025 | G23: 6673071 | H23: =(G23/G22)-1 -> 0.0077620867 | I23: =H23+1 -> 1.0077621
A27: Using DSEX Index data of 20 years (2005-2025)
A28: Market Return (Rm) | C28: =GEOMEAN(D4:D23)-1 -> 0.056704214

Sheet Cost of Equity
A1: Cost of Equity using the Gordon Growth Model
A2: Year | B2: Cash Dividend | C2: Growth Rate
A3: 2018 | B3: 30381750
A4: 2019 | B4: 26301675 | C4: =(B4/B3)-1 -> -0.13429361
A5: 2020 | B5: 28110077 | C5: =(B5/B4)-1 -> 0.068756153
A6: 2021 | B6: 33058662 | C6: =(B6/B5)-1 -> 0.1760431
A7: 2022 | B7: 33584032 | C7: =(B7/B6)-1 -> 0.015892053
A8: 2023 | B8: 9093155 | C8: =(B8/B7)-1 -> -0.72924171
A9: 2024 | B9: 42317213 | C9: =(B9/B8)-1 -> 3.6537437
A11: CAGR (g) | B11: =((B9/B3)^(1/7))-1 -> 0.048474212
A12: Current Market price (P0) | B12: 279
A13: Dividend of last year (2024_D0) | B13: 33
A14: Current Year Dividend (2025_D1) | B14: =B13*(1+B11) -> 34.599649
A15: Ke | B15: =(B14/B12)+B11 -> 0.17248729
A21: 1. Total cash dividends fpr 7 years were used to find the Compunded Annual Growth Rate (CAGR).
A22: 2. Similarily, 6 years data has been used to calculate the Sustainable Growth Rate (SGR) to observe an alternative g rate
A23: 3. CAGR is a better method of growth rate (compounding factor)
A24: 4. Latest market price has been taken (4th Dec, 2025)
A25: 5. Dividend per share for 2024 has been taken from the Annual Report of GP 2024
A26: 6. All the information was then plugged in the DDM formula.

Sheet Cost of Debt
A1: Year | B1: 2025 | C1: 2024 | D1: 2023 | E1: 2022 | F1: 2021 | G1: 2020 | H1: 2019
A2: Cash & Cash Equivalents | B2: 15706467000 | C2: 7334432000 | D2: 16718338000 | E2: 3325922000 | F2: 2748661000 | G2: 2598738000 | H2: 13760677000
A4: Loans & Borrowings | B4: 0 | C4: 5000000000 | D4: 3119599000 | E4: 5037394000 | F4: 5500000000 | G4: 1240000000 | H4: 2934284000
A5: Lease Liabilities | B5: =48233913000+10925359000 -> 59159272000 | C5: =48853886000+11112469000 -> 59966355000 | D5: =40212825000+10006247000 -> 50219072000 | E5: =41046666000+10852496000 -> 51899162000 | F5: =22675135000+9445609000 -> 32120744000 | G5: =14146840000+6328697000 -> 20475537000 | H5: =13484106000+7349549000 -> 20833655000
A7: Net Debt | B7: =SUM(B4:B5)-B2 -> 43452805000 | C7: =SUM(C4:C5)-SUM(C2:C2) -> 57631923000 | D7: =SUM(D4:D5)-SUM(D2:D2) -> 36620333000 | E7: =SUM(E4:E5)-SUM(E2:E2) -> 53610634000 | F7: =SUM(F4:F5)-SUM(F2:F2) -> 34872083000 | G7: =SUM(G4:G5)-SUM(G2:G2) -> 19116799000 | H7: =SUM(H4:H5)-SUM(H2:H2) -> 10007262000
A10: Interest Expense | B10: 53214000 | C10: 451408000 | D10: 668820000 | E10: 156852000 | F10: 87206000 | G10: 1245125000 | H10: 804706000
A11: Lease Interest | B11: 1418588000 | C11: 4949207000 | D11: 4706978000 | E11: 3254319000 | F11: 2495806000 | G11: 1803873000 | H11: 2121092000
A12: Interest Income | B12: 168926000 | C12: 715732000 | D12: 352911000 | E12: 456720000 | F12: 147881000 | G12: 376627000 | H12: 597542000
A14: Net Interest Expense | B14: =SUM(B10:B11)-B12 -> 1302876000 | C14: =SUM(C10:C11)-C12 -> 4684883000 | D14: =SUM(D10:D11)-D12 -> 5022887000 | E14: =SUM(E10:E11)-E12 -> 2954451000 | F14: =SUM(F10:F11)-F12 -> 2435131000 | G14: =SUM(G10:G11)-G12 -> 2672371000 | H14: =SUM(H10:H11)-H12 -> 2328256000
A17: Income before Tax | B17: 11005978000 | C17: 53543224000 | D17: 54323873000 | E17: 30091598000 | F17: 34129056000 | G17: 37187037000 | H17: 34516760000
A18: Income Tax Expense | B18: 4666667000 | C18: 17234497000 | D18: 21249000000 | E18: 21898505000 | F18: 26691690000 | G18: 25613869000 | H18: 29382199000
A20: Tax Rate | B20: =B18/B17 -> 0.42401202 | C20: =C18/C17 -> 0.32188008 | D20: =D18/D17 -> 0.391154 | E20: =E18/E17 -> 0.72772822 | F20: =F18/F17 -> 0.78208111 | G20: =G18/G17 -> 0.68878488 | H20: =H18/H17 -> 0.85124441
A23: Lease liabilities are included in net debt because, under IFRS 16, long term leases are treated like interest-bearing financing, not just operating costs. Grameenphone pays regular finance charges on these obligations so they are similar to loans and directly contribute to the true cost of debt capital.
A28: Year | B28: Net Debt | C28: Average Net Debt | D28: Net Interest | E28: Pre-tax Cost of Debt
A29: 2019 | B29: 10007262000 | D29: 2328256000
A30: 2020 | B30: 19116799000 | C30: =AVERAGE(B29,B30) -> 14562030500 | D30: 2672371000 | E30: =D30/C30 -> 0.18351637
A31: 2021 | B31: 34872083000 | C31: =AVERAGE(B30,B31) -> 26994441000 | D31: 2435131000 | E31: =D31/C31 -> 0.09020861
A32: 2022 | B32: 53610634000 | C32: =AVERAGE(B31,B32) -> 44241358500 | D32: 2954451000 | E32: =D32/C32 -> 0.066780296
A33: 2023 | B33: 36620333000 | C33: =AVERAGE(B32,B33) -> 45115483500 | D33: 5022887000 | E33: =D33/C33 -> 0.11133399
A34: 2024 | B34: 57631923000 | C34: =AVERAGE(B33,B34) -> 47126128000 | D34: 4684883000 | E34: =D34/C34 -> 0.099411583
A35: 2025 | B35: 43452805000 | C35: =AVERAGE(B34,B35) -> 50542364000 | D35: 1302876000 | E35: =D35/C35 -> 0.0257779
C36: =SUM(C30:C35) -> 228581805500 | D36: =SUM(D30:D35) -> 19072599000 | E36: =D36/C36 -> 0.083438833
A39: The 8.34% is the historical rate which shows what Grameenphone effectively paid on its debt over the years of 2020 to 2025.
A44: Year | B44: Tax Rates | E44: Market Cost of Debt (pre-tax) | F44: 0.1244
A45: 2019 | B45: 0.85124441 | E45: Cost of Debt | F45: =F44*(1-B52) -> 0.049993077
A46: 2020 | B46: 0.68878488
A47: 2021 | B47: 0.78208111
A48: 2022 | B48: 0.72772822
A49: 2023 | B49: 0.391154
A50: 2024 | B50: 0.32188008
A51: 2025 | B51: 0.42401202
B52: =AVERAGE(B45:B51) -> 0.59812639
A54: Statutory Tax Rate | B54: 0.4

Sheet WACC
A1: Cost of Equity | B1: =[2]CAPM!M14 -> 0.14200259
A3: After-tax Cost of Debt | B3: ='[2]Debt Calculations'!F47 -> 0.049993077
A5: EQUITY:
A6: Share Price | B6: 278.4
A7: Number of Shares Outstanding | B7: 1350300022
A9: DEBT:
A10: Year | B10: 2025 | C10: 2024 | D10: 2023 | E10: 2022 | F10: 2021 | G10: 2020 | H10: 2019
A11: Loans & Borrowings | B11: 0 | C11: 5000000000 | D11: 3119599000 | E11: 5037394000 | F11: 5500000000 | G11: 1240000000 | H11: 2934284000
A12: Lease Liabilities | B12: 59159272000 | C12: 59966355000 | D12: 50219072000 | E12: 51899162000 | F12: 32120744000 | G12: 20475537000 | H12: 20833655000
A13: Total Debt | B13: =B11+B12 -> 59159272000 | C13: =C11+C12 -> 64966355000 | D13: =D11+D12 -> 53338671000 | E13: =E11+E12 -> 56936556000 | F13: =F11+F12 -> 37620744000 | G13: =G11+G12 -> 21715537000 | H13: =H11+H12 -> 23767939000
A15: Market Value of Debt | B15: =AVERAGE(B13:H13) -> 4.5357868e+10
A16: Market Value of Equity | B16: =B7*B6 -> 3.7592353e+11
A17: WACC | B17: =(B16/(B16+B15)*B1)+(B15/(B15+B16)*B3) -> 0.13209626

Sheet Income Statement
A1: Income Statement [Historical] | J1: Income Statement [Common Sized]
A2: Particulars | B2: 2019 | C2: 2020 | D2: 2021 | E2: 2022 | F2: 2023 | G2: 2024 | J2: Particulars | K2: 2019 | L2: 2020 | M2: 2021 | N2: 2022 | O2: 2023 | P2: 2024
A3: Revenue | B3: 143656271 | C3: 139606161 | D3: 143065872 | E3: 150403469 | F3: 158715818 | G3: 158447003 | J3: Revenue | K3: 1 | L3: 1 | M3: 1 | N3: 1 | O3: 1 | P3: 1
A4: Cost of material and traffic charges | B4: -8465283 | C4: -8812905 | D4: -9604705 | E4: -10088492 | F4: -9961041 | G4: -9825692 | J4: Cost of material and traffic charges | K4: ='Income Statement'!K4/'Income Statement'!$B$3*-1 -> 0.058927347 | L4: ='Income Statement'!L4/'Income Statement'!$C$3*-1 -> 0.063126906 | M4: ='Income Statement'!M4/'Income Statement'!$D$3*-1 -> 0.067134844 | N4: ='Income Statement'!N4/'Income Statement'!$E$3*-1 -> 0.067076192 | O4: ='Income Statement'!O4/'Income Statement'!$F$3*-1 -> 0.062760228 | P4: ='Income Statement'!P4/'Income Statement'!$G$3*-1 -> 0.062012482
A5: Revenue sharing, spectrum charges and licence fees | B5: -10107313 | C5: -10478334 | D5: -10895286 | E5: -12583383 | F5: -12009842 | G5: -12068041 | J5: Revenue sharing, spectrum charges and licence fees | K5: ='Income Statement'!K5/'Income Statement'!$B$3*-1 -> 0.070357618 | L5: ='Income Statement'!L5/'Income Statement'!$C$3*-1 -> 0.075056387 | M5: ='Income Statement'!M5/'Income Statement'!$D$3*-1 -> 0.076155731 | N5: ='Income Statement'!N5/'Income Statement'!$E$3*-1 -> 0.083664181 | O5: ='Income Statement'!O5/'Income Statement'!$F$3*-1 -> 0.075668841 | P5: ='Income Statement'!P5/'Income Statement'!$G$3*-1 -> 0.076164527
A6: Gross Profit | B6: =B3+B4+B5 -> 125083675 | C6: =C3+C4+C5 -> 120314922 | D6: =D3+D4+D5 -> 122565881 | E6: =E3+E4+E5 -> 127731594 | F6: =F3+F4+F5 -> 136744935 | G6: =G3+G4+G5 -> 136553270 | J6: Gross Profit | K6: ='Income Statement'!K6/'Income Statement'!$B$3 -> 0.87071503 | L6: ='Income Statement'!L6/'Income Statement'!$C$3 -> 0.86181671 | M6: ='Income Statement'!M6/'Income Statement'!$D$3 -> 0.85670943 | N6: ='Income Statement'!N6/'Income Statement'!$E$3 -> 0.84925963 | O6: ='Income Statement'!O6/'Income Statement'!$F$3 -> 0.86157093 | P6: ='Income Statement'!P6/'Income Statement'!$G$3 -> 0.86182299
A7: Salaries and personnel cost | B7: -9437578 | C7: -10027226 | D7: -11507572 | E7: -9235728 | F7: -8494009 | G7: -8517867 | J7: Salaries and personnel cost | K7: ='Income Statement'!K7/'Income Statement'!$B$3*-1 -> 0.065695552 | L7: ='Income Statement'!L7/'Income Statement'!$C$3*-1 -> 0.071825097 | M7: ='Income Statement'!M7/'Income Statement'!$D$3*-1 -> 0.080435479 | N7: ='Income Statement'!N7/'Income Statement'!$E$3*-1 -> 0.06140635 | O7: ='Income Statement'!O7/'Income Statement'!$F$3*-1 -> 0.053517092 | P7: ='Income Statement'!P7/'Income Statement'!$G$3*-1 -> 0.053758461
A8: Operation and maintenance | B8: -5898863 | C8: -4984745 | D8: -5550948 | E8: -4252580 | F8: -6272385 | G8: -6942686 | J8: Operation and maintenance | K8: ='Income Statement'!K8/'Income Statement'!$B$3*-1 -> 0.041062342 | L8: ='Income Statement'!L8/'Income Statement'!$C$3*-1 -> 0.035705767 | M8: ='Income Statement'!M8/'Income Statement'!$D$3*-1 -> 0.038799945 | N8: ='Income Statement'!N8/'Income Statement'!$E$3*-1 -> 0.028274481 | O8: ='Income Statement'!O8/'Income Statement'!$F$3*-1 -> 0.039519596 | P8: ='Income Statement'!P8/'Income Statement'!$G$3*-1 -> 0.043817086
A9: Sales, marketing and commissions | B9: -13480018 | C9: -11771112 | D9: -13341089 | E9: -15278933 | F9: -15428172 | G9: -16247666 | J9: Sales, marketing and commissions | K9: ='Income Statement'!K9/'Income Statement'!$B$3*-1 -> 0.093835221 | L9: ='Income Statement'!L9/'Income Statement'!$C$3*-1 -> 0.084316565 | M9: ='Income Statement'!M9/'Income Statement'!$D$3*-1 -> 0.093251373 | N9: ='Income Statement'!N9/'Income Statement'!$E$3*-1 -> 0.10158631 | O9: ='Income Statement'!O9/'Income Statement'!$F$3*-1 -> 0.097206266 | P9: ='Income Statement'!P9/'Income Statement'!$G$3*-1 -> 0.10254322
A10: Depreciation and amortisation | B10: -23451039 | C10: -23649950 | D10: -23016177 | E10: -27899584 | F10: -32321703 | G10: -34551840 | J10: Depreciation and amortisation | K10: ='Income Statement'!K10/'Income Statement'!$B$3*-1 -> 0.1632441 | L10: ='Income Statement'!L10/'Income Statement'!$C$3*-1 -> 0.16940477 | M10: ='Income Statement'!M10/'Income Statement'!$D$3*-1 -> 0.16087818 | N10: ='Income Statement'!N10/'Income Statement'!$E$3*-1 -> 0.18549827 | O10: ='Income Statement'!O10/'Income Statement'!$F$3*-1 -> 0.20364513 | P10: ='Income Statement'!P10/'Income Statement'!$G$3*-1 -> 0.2180656
A11: Operating Profit | B11: =B6+B7+B8+B9+B10 -> 72816177 | C11: =C6+C7+C8+C9+C10 -> 69881889 | D11: =D6+D7+D8+D9+D10 -> 69150095 | E11: =E6+E7+E8+E9+E10 -> 71064769 | F11: =F6+F7+F8+F9+F10 -> 74228666 | G11: 59129211 | J11: Operating Profit | K11: ='Income Statement'!K11/'Income Statement'!$B$3 -> 0.50687782 | L11: ='Income Statement'!L11/'Income Statement'!$C$3 -> 0.50056451 | M11: ='Income Statement'!M11/'Income Statement'!$D$3 -> 0.48334445 | N11: ='Income Statement'!N11/'Income Statement'!$E$3 -> 0.47249421 | O11: ='Income Statement'!O11/'Income Statement'!$F$3 -> 0.46768285 | P11: ='Income Statement'!P11/'Income Statement'!$G$3 -> 0.37317974
A12: Other operating (expenses)/income | B12: -6164349 | C12: -6442284 | D12: -5814523 | E12: -7466582 | F12: -9799694 | G12: -11164000 | J12: Other operating (expenses)/income | K12: ='Income Statement'!K12/'Income Statement'!$B$3*-1 -> 0.042910407 | L12: ='Income Statement'!L12/'Income Statement'!$C$3*-1 -> 0.04614613 | M12: ='Income Statement'!M12/'Income Statement'!$D$3*-1 -> 0.040642278 | N12: ='Income Statement'!N12/'Income Statement'!$E$3*-1 -> 0.049643682 | O12: ='Income Statement'!O12/'Income Statement'!$F$3*-1 -> 0.061743651 | P12: ='Income Statement'!P12/'Income Statement'!$G$3*-1 -> 0.07045889
A13: Finance (expense)/income | B13: -2523060 | C13: -376473 | D13: -2595396 | E13: -10177407 | F13: -9383833 | G13: -4986593 | J13: Finance (expense)/income | K13: ='Income Statement'!K13/'Income Statement'!$B$3*-1 -> 0.017563173 | L13: ='Income Statement'!L13/'Income Statement'!$C$3*-1 -> 0.002696679 | M13: ='Income Statement'!M13/'Income Statement'!$D$3*-1 -> 0.018141266 | N13: ='Income Statement'!N13/'Income Statement'!$E$3*-1 -> 0.067667369 | O13: ='Income Statement'!O13/'Income Statement'!$F$3*-1 -> 0.05912349 | P13: ='Income Statement'!P13/'Income Statement'!$G$3*-1 -> 0.031471678
A14: Foreign exchange (loss)/gain | B14: -229809 | C14: -262226 | D14: 80570 | E14: -1430677 | F14: -721266 | G14: -599394 | J14: Foreign exchange (loss)/gain | K14: ='Income Statement'!K14/'Income Statement'!$B$3*-1 -> 0.0015997144 | L14: ='Income Statement'!L14/'Income Statement'!$C$3*-1 -> 0.0018783268 | M14: ='Income Statement'!M14/'Income Statement'!$D$3 -> 0.00056316715 | N14: ='Income Statement'!N14/'Income Statement'!$E$3*-1 -> 0.0095122607 | O14: ='Income Statement'!O14/'Income Statement'!$F$3*-1 -> 0.0045443864 | P14: ='Income Statement'!P14/'Income Statement'!$G$3*-1 -> 0.0037829305
A15: Profit before tax | B15: =B11+B12+B13+B14 -> 63898959 | C15: =C11+C12+C13+C14 -> 62800906 | D15: =D11+D12+D13+D14 -> 60820746 | E15: =E11+E12+E13+E14 -> 51990103 | F15: =F11+F12+F13+F14 -> 54323873 | G15: =G11+G12+G13+G14 -> 42379224 | J15: Profit before tax | K15: ='Income Statement'!K15/'Income Statement'!$B$3 -> 0.44480452 | L15: ='Income Statement'!L15/'Income Statement'!$C$3 -> 0.44984337 | M15: ='Income Statement'!M15/'Income Statement'!$D$3 -> 0.42512407 | N15: ='Income Statement'!N15/'Income Statement'!$E$3 -> 0.3456709 | O15: ='Income Statement'!O15/'Income Statement'!$F$3 -> 0.34227132 | P15: ='Income Statement'!P15/'Income Statement'!$G$3 -> 0.26746624
A16: Income tax expense | B16: -29382199 | C16: -25613869 | D16: -26691690 | E16: -21898505 | F16: -21249000 | G16: -17234497 | J16: Income tax expense | K16: ='Income Statement'!K16/'Income Statement'!$B$3*-1 -> 0.20453127 | L16: ='Income Statement'!L16/'Income Statement'!$C$3*-1 -> 0.18347234 | M16: ='Income Statement'!M16/'Income Statement'!$D$3*-1 -> 0.18656923 | N16: ='Income Statement'!N16/'Income Statement'!$E$3*-1 -> 0.1455984 | O16: ='Income Statement'!O16/'Income Statement'!$F$3*-1 -> 0.1338808 | P16: ='Income Statement'!P16/'Income Statement'!$G$3*-1 -> 0.10877137
A17: Profit after tax | B17: =B15+B16 -> 34516760 | C17: =C15+C16 -> 37187037 | D17: =D15+D16 -> 34129056 | E17: =E15+E16 -> 30091598 | F17: =F15+F16 -> 33074873 | G17: =G15+G16 -> 25144727 | J17: Profit after tax | K17: ='Income Statement'!K17/'Income Statement'!$B$3 -> 0.24027326 | L17: ='Income Statement'!L17/'Income Statement'!$C$3 -> 0.26637103 | M17: ='Income Statement'!M17/'Income Statement'!$D$3 -> 0.23855484 | N17: ='Income Statement'!N17/'Income Statement'!$E$3 -> 0.2000725 | O17: ='Income Statement'!O17/'Income Statement'!$F$3 -> 0.20839053 | P17: ='Income Statement'!P17/'Income Statement'!$G$3 -> 0.15869487
A18: Other comprehensive income | J18: Other comprehensive income
A19: Item that will not be reclassified subsequently to profit or loss | J19: Item that will not be reclassified subsequently to profit or loss
A20: Remeasurement of defined benefit plan | B20: 127659 | C20: -783080 | D20: 166647 | E20: -3164 | F20: 386265 | G20: 379566 | J20: Remeasurement of defined benefit plan | K20: ='Income Statement'!K20/'Income Statement'!$B$3 -> 0.00088864203 | L20: ='Income Statement'!L20/'Income Statement'!$C$3*-1 -> 0.005609208 | M20: ='Income Statement'!M20/'Income Statement'!$D$3 -> 0.0011648271 | N20: ='Income Statement'!N20/'Income Statement'!$E$3 -> -2.1036749e-05 | O20: ='Income Statement'!O20/'Income Statement'!$F$3 -> 0.0024336894 | P20: ='Income Statement'!P20/'Income Statement'!$G$3 -> 0.0023955392
A21: Related taxes | B21: -51063 | C21: 313232 | D21: -66659 | E21: 1266 | F21: -154506 | G21: -151826 | J21: Related taxes | K21: ='Income Statement'!K21/'Income Statement'!$B$3*-1 -> 0.00035545263 | L21: ='Income Statement'!L21/'Income Statement'!$C$3 -> 0.0022436832 | M21: ='Income Statement'!M21/'Income Statement'!$D$3*-1 -> 0.00046593222 | N21: ='Income Statement'!N21/'Income Statement'!$E$3 -> 8.417359e-06 | O21: ='Income Statement'!O21/'Income Statement'!$F$3*-1 -> 0.00097347575 | P21: ='Income Statement'!P21/'Income Statement'!$G$3*-1 -> 0.00095821314
A22: Total comprehensive income for the year | B22: =B17+B20+B21 -> 34593356 | C22: =C17+C20-C21 -> 36090725 | D22: =D17-D20+D21 -> 33895750 | E22: =E17+E20-E21 -> 30087168 | F22: =F17-F20+F21 -> 32534102 | G22: =G17-G20+G21 -> 24613335 | J22: Total comprehensive income for the year | K22: ='Income Statement'!K22/'Income Statement'!$B$3 -> 0.24080645 | L22: ='Income Statement'!L22/'Income Statement'!$C$3 -> 0.25851814 | M22: ='Income Statement'!M22/'Income Statement'!$D$3 -> 0.23692408 | N22: ='Income Statement'!N22/'Income Statement'!$E$3 -> 0.20004305 | O22: ='Income Statement'!O22/'Income Statement'!$F$3 -> 0.20498336 | P22: ='Income Statement'!P22/'Income Statement'!$G$3 -> 0.15534112
A23: Earnings per share
A24: Basic earnings per share
A25: (per value BDT 10 each in BDT) | B25: 25.56 | C25: 27.54 | D25: 25.28 | E25: 22.29 | F25: 24.49 | G25: 26.89

Sheet Balance Sheet
A1: Balance Sheet [Historical] | I1: Balance Sheet [Common Sized]
A2: Particulars | B2: 2019 | C2: 2020 | D2: 2021 | E2: 2022 | F2: 2023 | G2: 2024 | I2: Particulars | J2: 2019 | K2: 2020 | L2: 2021 | M2: 2022 | N2: 2023 | O2: 2024
A3: Assets | I3: Assets
A4: Non-current assets | I4: Non-current assets
A5: Property, plant and equipment | B5: 62,396,558 | C5: 56901192 | D5: 60,387,950 | E5: 62849119 | F5: 67019995 | G5: 68,335,441 | I5: Property, plant and equipment | J5: 0.41951659 | K5: 0.3839893 | L5: 0.37046304 | M5: 0.33956452 | N5: 0.33439739 | O5: 0.34364763
A6: Intangible assets | B6: 2,274,803 | C6: 2316587 | D6: 3,632,296 | E6: 4023092 | F6: 4396001 | G6: 4,774,439 | I6: Intangible assets | J6: 0.015294395 | K6: 0.015633146 | L6: 0.022283111 | M6: 0.021736172 | N6: 0.021933921 | O6: 0.024009864
A7: Right-of-use assets | B7: 58,028,533 | C7: 53532673 | D7: 62,533,832 | E7: 80501010 | F7: 76086723 | G7: 77,710,892 | I7: Right-of-use assets | J7: 0.39014864 | K7: 0.36125735 | L7: 0.38362742 | M7: 0.43493508 | N7: 0.37963598 | O7: 0.39079523
A8: Contract cost | B8: 4,480,157 | C8: 4934438 | D8: 6,035,958 | E8: 5148908 | F8: 7141432 | G8: 10,436,997 | I8: Contract cost | J8: 0.030121857 | K8: 0.033299327 | L8: 0.0370289 | M8: 0.02781879 | N8: 0.035632295 | O8: 0.052485932
A9: Other non-current assets | B9: 555,200 | C9: 20568456 | D9: 20,549,067 | E9: 20471567 | F9: 20471568 | G9: 1,458,619 | I9: Other non-current assets | J9: 0.0037328279 | K9: 0.13880319 | L9: 0.12606273 | M9: 0.11060486 | N9: 0.10214323 | O9: 0.0073351538
A10: Total non-current assets | B10: 127,735,251 | C10: 138,253,346 | D10: 153,139,103 | E10: 172993696 | F10: 175115719 | G10: 20,526,814 | I10: Total non-current assets | J10: 0.85881432 | K10: 0.93298231 | L10: 0.9394652 | M10: 0.93465942 | N10: 0.87374283 | O10: 0.10322595
A11: Current assets | I11: Current assets
A12: Inventories | B12: 225,441 | C12: 201068 | D12: 260,230 | E12: 1088393 | F12: 591449 | G12: 407655 | I12: Inventories | J12: 0.0015157285 | K12: 0.0013568777 | L12: 0.0015964376 | M12: 0.0058804268 | N12: 0.0029510447 | O12: 0.0020500296
A13: Trade receivables and others | B13: 7,013,053 | C13: 7131165 | D13: 6,858,686 | E13: 7679405 | F13: 7994702 | G13: 7,867,938 | I13: Trade receivables and others | J13: 0.047151513 | K13: 0.048123615 | L13: 0.042076104 | M13: 0.041490692 | N13: 0.0398897 | O13: 0.039566559
A14: Cash and cash equivalents | B14: 13,760,677 | C14: 2598738 | D14: 2,748,661 | E14: 3325922 | F14: 16718338 | G14: 7,334,432 | I14: Cash and cash equivalents | J14: 0.092518442 | K14: 0.0175372 | L14: 0.01686226 | M14: 0.017969466 | N14: 0.083416429 | O14: 0.036883646
A15: Total current assets | B15: 20,999,171 | C15: 9,930,971 | D15: 9,867,577 | E15: 12093720 | F15: 25304489 | G15: 15,610,025 | I15: Total current assets | J15: 0.14118568 | K15: 0.067017693 | L15: 0.060534801 | M15: 0.065340585 | N15: 0.12625717 | O15: 0.078500235
A16: Total assets | B16: 148,734,422 | C16: 148,184,317 | D16: 163,006,680 | E16: 185087416 | F16: 200420208 | G16: 198,853,227 | I16: Total assets | J16: 1 | K16: 1 | L16: 1 | M16: 1 | N16: 1 | O16: 1
A17: Equity and liabilities | I17: Equity and liabilities
A18: Shareholders’ equity | I18: Shareholders’ equity
A19: Share capital | B19: 13,503,000 | C19: 13503000 | D19: 13,503,000 | E19: 13503000 | F19: 13503000 | G19: 13503000 | I19: Share capital | J19: 0.090785978 | K19: 0.091123003 | L19: 0.082837096 | M19: 0.072954717 | N19: 0.067373446 | O19: 0.067904354
A20: Share premium | B20: 7,840,226 | C20: 7840226 | D20: 7,840,226 | E20: 7840226 | F20: 7840226 | G20: 7,840,226 | I20: Share premium | J20: 0.052712922 | K20: 0.052908608 | L20: 0.048097575 | M20: 0.042359584 | N20: 0.03911894 | O20: 0.0394272
A21: Capital reserve | B21: 14,446 | C21: 14446 | D21: 14,446 | E21: 14446 | F21: 14446 | G21: 14,446 | I21: Capital reserve | J21: 9.7126138e-05 | K21: 9.74867e-05 | L21: 8.8622135e-05 | M21: 7.8049607e-05 | N21: 7.207856e-05 | O21: 7.2646545e-05
A22: Deposit from shareholders | B22: 1,880 | I22: Deposit from shareholders | J22: 1.2639979e-05 | K22: 0 | L22: 0 | M22: 0 | N22: 0 | O22: 0
A23: Retained earnings | B23: 16,987,853 | C23: 30749942 | D23: 28,520,886 | E23: 24853086 | F23: 45331868 | G23: 43,384,785 | I23: Retained earnings | J23: 0.11421602 | K23: 0.20751145 | L23: 0.17496759 | M23: 0.13427756 | N23: 0.22618412 | O23: 0.21817491
A24: Total equity | B24: 38,347,405 | C24: 52,107,614 | D24: 49,878,558 | E24: 46210758 | F24: 66689540 | G24: 64,742,457 | I24: Total equity | J24: 0.25782468 | K24: 0.35164055 | L24: 0.30599088 | M24: 0.24966991 | N24: 0.33274858 | O24: 0.32557911
A25: Non-current liabilities | I25: Non-current liabilities
A26: Lease liabilities | B26: 13,484,106 | C26: 14146840 | D26: 22,675,135 | E26: 41046666 | F26: 40212825 | G26: 48,853,886 | I26: Lease liabilities | J26: 0.090658946 | K26: 0.095467862 | L26: 0.13910556 | M26: 0.22176908 | N26: 0.20064257 | O26: 0.24567812
A27: Deferred tax liabilities | B27: 5,216,029 | C27: 3350834 | D27: 3,425,488 | E27: 3060593 | F27: 479369 | G27: - | I27: Deferred tax liabilities | J27: 0.035069414 | K27: 0.022612609 | L27: 0.021014403 | M27: 0.016535932 | N27: 0.0023918197 | O27: -
A28: Employee benefits | B28: 936,703 | C28: 1641383 | D28: 1,336,085 | E28: 1340324 | F28: 384470 | G28: 395,836 | I28: Employee benefits | J28: 0.0062978226 | K28: 0.011076631 | L28: 0.0081965046 | M28: 0.0072415728 | N28: 0.0019183195 | O28: 0.0019905938
A29: Other non-current liabilities | B29: 323,957 | C29: 281272 | D29: 455,308 | E29: 496323 | F29: 456235 | G29: 546,133 | I29: Other non-current liabilities | J29: 0.0021780903 | K29: 0.0018981226 | L29: 0.0027931861 | M29: 0.0026815599 | N29: 0.0022763922 | O29: 0.0027464126
A30: Total non-current liabilities | B30: 19,960,795 | C30: 19,420,329 | D30: 27,892,016 | E30: 45943906 | F30: 41532899 | G30: 49,795,855 | I30: Total non-current liabilities | J30: 0.13420427 | K30: 0.13105522 | L30: 0.17110965 | M30: 0.24822815 | N30: 0.2072291 | O30: 0.25041512
A31: Current liabilities | I31: Current liabilities
A32: Trade payables and others | B32: 22,676,406 | C32: 23988115 | D32: 25,521,622 | E32: 27275330 | F32: 29619417 | G32: 28,366,808 | I32: Trade payables and others | J32: 0.15246239 | K32: 0.16188025 | L32: 0.15656795 | M32: 0.14736458 | N32: 0.14778658 | O32: 0.14265199
A33: Provisions | B33: 18,839,102 | C33: 14402559 | D33: 15,703,449 | E33: 23612398 | F33: 23946716 | G33: 24,920,485 | I33: Provisions | J33: 0.12666269 | K33: 0.097193544 | L33: 0.09633623 | M33: 0.1275743 | N33: 0.11948254 | O33: 0.125321
A34: Lease liabilities | B34: 7,349,549 | C34: 6328697 | D34: 9,445,609 | E34: 10852496 | F34: 10006247 | G34: 11,112,469 | I34: Lease liabilities | J34: 0.049413908 | K34: 0.042708278 | L34: 0.057946147 | M34: 0.058634435 | N34: 0.049926338 | O34: 0.055882769
A35: Loans and borrowings | B35: 2,934,284 | C35: 1240000 | D35: 5,500,000 | E35: 5037394 | F35: 3119599 | G35: 5,000,000 | I35: Loans and borrowings | J35: 0.019728345 | K35: 0.008367957 | L35: 0.033740949 | M35: 0.027216297 | N35: 0.015565292 | O35: 0.025144173
A36: Current tax liabilities | B36: 28,137,225 | C36: 24870650 | D36: 25,603,868 | E36: 23779920 | F36: 19459679 | G36: 12,769,919 | I36: Current tax liabilities | J36: 0.18917763 | K36: 0.16783591 | L36: 0.15707251 | M36: 0.1284794 | N36: 0.097094396 | O36: 0.064217811
A37: Other current liabilities | B37: 10,489,656 | C37: 5690023 | D37: 3,414,334 | E37: 2316342 | F37: 5968502 | G37: 2,077,180 | I37: Other current liabilities | J37: 0.070526082 | K37: 0.038398281 | L37: 0.020945976 | M37: 0.012514854 | N37: 0.029779941 | O37: 0.010445795
A38: Unclaimed Dividend | C38: 136330 | D38: 47,224 | E38: 58872 | F38: 77609 | G38: 68,054 | I38: Unclaimed Dividend | J38: 0 | K38: 0.00092000289 | L38: 0.00028970592 | M38: 0.00031807673 | N38: 0.00038723141 | O38: 0.00034223231
A39: Total current liabilities | B39: 90,426,222 | C39: 76,656,374 | D39: 85,236,106 | E39: 92932752 | F39: 92197769 | G39: 84,314,915 | I39: Total current liabilities | J39: 0.60797105 | K39: 0.51730423 | L39: 0.52289947 | M39: 0.50210195 | N39: 0.46002232 | O39: 0.42400577
A40: Total equity and liabilities | B40: 148,734,422 | C40: 148,184,317 | D40: 163,006,680 | E40: 185087416 | F40: 200420208 | G40: 198,853,227 | I40: Total equity and liabilities | J40: 1 | K40: 1 | L40: 1 | M40: 1 | N40: 1 | O40: 1

Sheet CAGR Based Sales forecast
A1: Year | B1: Cash Dividend | C1: Growth Rate | D1: CAGR (g) | E1: =((B8/B2)^(1/7))-1 -> 0.048474212
A2: 2018 | B2: 30381750 | D2: Current Market price (P0) | E2: 279
A3: 2019 | B3: 26301675 | C3: =(B3/B2)-1 -> -0.13429361 | D3: Dividend of last year (2024_D0) | E3: 33
A4: 2020 | B4: 28110077 | C4: =(B4/B3)-1 -> 0.068756153 | D4: Current Year Dividend (2025_D1) | E4: =E3*(1+E1) -> 34.599649
A5: 2021 | B5: 33058662 | C5: =(B5/B4)-1 -> 0.1760431
A6: 2022 | B6: 33584032 | C6: =(B6/B5)-1 -> 0.015892053
A7: 2023 | B7: 9093155 | C7: =(B7/B6)-1 -> -0.72924171
A8: 2024 | B8: 42317213 | C8: =(B8/B7)-1 -> 3.6537437
D11: Particulars | E11: 2019 | F11: 2020 | G11: 2021 | H11: 2022 | I11: 2023 | J11: 2024
D12: Revenue | E12: 143656271 | F12: 139606161 | G12: 143065872 | H12: 150403469 | I12: 158715818 | J12: 158447003
D15: Forecasted Revenue Using CAGR in BDT | E15: 2025 | F15: 2026 | G15: 2027 | H15: 2028 | I15: 2029 | J15: 2030
E16: =J12*(1+E1) -> 1.661276e+08 | F16: =E16*(1+E1) -> 1.741805e+08 | G16: =F16*(1+E1) -> 1.8262376e+08 | H16: =G16*(1+E1) -> 1.9147631e+08 | I16: =H16*(1+E1) -> 2.0075797e+08 | J16: =I16*(1+E1) -> 2.1048955e+08

Sheet Top-Down Based Sales forecast
A1: Top-Down Input
B2: Actual
A3: Year | B3: 2019 | C3: 2020 | D3: 2021 | E3: 2022 | F3: 2023 | G3: 2024
A4: Population | B4: =163.05*10^6 -> 163050000 | C4: =164.69*10^6 -> 164690000 | D4: =166.66*10^6 -> 166660000 | E4: =168.52*10^6 -> 168520000 | F4: =170.28*10^6 -> 170280000 | G4: =172.02*10^6 -> 172020000
A5: GDP Growth | B5: 0.1183 | C5: 0.0742 | D5: 0.1135 | E5: 0.1251 | F5: 0.1307 | G5: 0.11397
A6: Inflation | B6: 0.0548 | C6: 0.0556 | D6: 0.0565 | E6: 0.0615 | F6: 0.0902 | G6: 0.0937
A7: Total Mobile Subscriptions | B7: 165570000 | C7: 170100000 | D7: 181020000 | E7: 180200000 | F7: 190810000 | G7: 187580000
A8: Year on Year % Change | C8: =C7/B7-1 -> 0.027360029 | D8: =D7/C7-1 -> 0.064197531 | E8: =E7/D7-1 -> -0.0045298862 | F8: =F7/E7-1 -> 0.058879023 | G8: =G7/F7-1 -> -0.016927834 | I8: Expected Growth | J8: =GEOMEAN(C8+1, D8+1, E8+1, F8+1, G8+1)-1 -> 0.025276437
A9: Grameenphone Subscriptions | B9: 76460000 | C9: 79040000 | D9: 83460000 | E9: 79290000 | F9: 82200000 | G9: 84520000
A10: Year on Year % Change | C10: =C9/B9-1 -> 0.033743134 | D10: =D9/C9-1 -> 0.055921053 | E10: =E9/D9-1 -> -0.049964055 | F10: =F9/E9-1 -> 0.036700719 | G10: =G9/F9-1 -> 0.028223844 | I10: Expected Growth | J10: =GEOMEAN(C10+1, D10+1, E10+1, F10+1, G10+1)-1 -> 0.020246325
A11: Grameenphone Market Share | B11: =B9/B7 -> 0.46179864 | C11: =C9/C7 -> 0.46466784 | D11: =D9/D7 -> 0.46105403 | E11: =E9/E7 -> 0.4400111 | F11: =F9/F7 -> 0.43079503 | G11: =G9/G7 -> 0.45058109 | H11: =_xlfn.FORMULATEXT(G11) -> =G9/G7
A12: Year on Year % Change | C12: =C11/B11-1 -> 0.0062131137 | D12: =D11/C11-1 -> -0.0077772011 | E12: =E11/D11-1 -> -0.045640917 | F12: =F11/E11-1 -> -0.020945079 | G12: =G11/F11-1 -> 0.045929159 | I12: Expected Growth | J12: =GEOMEAN(C12+1, D12+1, E12+1, F12+1, G12+1)-1 -> -0.0049061037
A13: GP ARPU (BDT/month) | B13: 157 | C13: 150 | D13: 143 | E13: 149 | F13: 161 | G13: 155
A14: Year on Year % Change | C14: =C13/B13-1 -> -0.044585987 | D14: =D13/C13-1 -> -0.046666667 | E14: =E13/D13-1 -> 0.041958042 | F14: =F13/E13-1 -> 0.080536913 | G14: =G13/F13-1 -> -0.037267081 | I14: Expected Growth | J14: =GEOMEAN(D14+1, E14+1, F14+1)-1 -> 0.023870128
A15: Mobile Data Users | B15: 40600000 | C15: 41300000 | D15: 44600000 | E15: 43600000 | F15: 46600000 | G15: 48000000
A16: Smartphone Users | B16: =B15/0.95 -> 42736842 | C16: =C15/0.95 -> 43473684 | D16: =D15/0.95 -> 46947368 | E16: =E15/0.95 -> 45894737 | F16: =F15/0.95 -> 49052632 | G16: =G15/0.95 -> 50526316 | H16: =_xlfn.FORMULATEXT(G16) -> =G15/0.95
A17: Year on Year % Change | C17: =C16/B16-1 -> 0.017241379 | D17: =D16/C16-1 -> 0.079903148 | E17: =E16/D16-1 -> -0.022421525 | F17: =F16/E16-1 -> 0.068807339 | G17: =G16/F16-1 -> 0.030042918 | I17: Expected Growth | J17: =GEOMEAN(C17+1, D17+1, E17+1, F17+1, G17+1)-1 -> 0.034053576
A18: GP Revenue (BDT bn) | B18: =B9*B13*12 -> 144050640000 | C18: =C9*C13*12 -> 142272000000 | D18: =D9*D13*12 -> 143217360000 | E18: =E9*E13*12 -> 141770520000 | F18: =F9*F13*12 -> 158810400000 | G18: =G9*G13*12 -> 157207200000 | H18: =_xlfn.FORMULATEXT(G18) -> =G9*G13*12
A19: Year on Year % Change | C19: =C18/B18-1 -> -0.012347325 | D19: =D18/C18-1 -> 0.0066447368 | E19: =E18/D18-1 -> -0.010102407 | F19: =F18/E18-1 -> 0.12019339 | G19: =G18/F18-1 -> -0.010095057
C20: =_xlfn.FORMULATEXT(C19) -> =C18/B18-1 | D20: =_xlfn.FORMULATEXT(D19) -> =D18/C18-1 | E20: =_xlfn.FORMULATEXT(E19) -> =E18/D18-1 | F20: =_xlfn.FORMULATEXT(F19) -> =F18/E18-1 | G20: =_xlfn.FORMULATEXT(G19) -> =G18/F18-1
A23: Top-Down Forecast
A24: Year | B24: Industry Subscription | C24: GP Market Share (%) | D24: GP Subscription | E24: ARPU (BDT/month) | F24: GP Revenue (BDT)
A25: 2024 | B25: =B35 -> 187580000 | C25: =B36 -> 0.45058109 | D25: =B25*C25 -> 84520000 | E25: =B37 -> 155 | F25: =D25*E25*12 -> 157207200000
A26: 2025 | B26: =B25*(1+$B$40) -> 1.9232135e+08 | C26: =C25*(1+$B$41) -> 0.44837049 | D26: =B26*C26 -> 86231219 | E26: =E25*(1+$B$42) -> 158.69987 | F26: =D26*E26*12 -> 1.642186e+11
A27: 2026 | B27: =B26*(1+$B$40) -> 1.9718255e+08 | C27: =C26*(1+$B$41) -> 0.44617074 | D27: =B27*C27 -> 87977085 | E27: =E26*(1+$B$42) -> 162.48806 | F27: =D27*E27*12 -> 1.7154271e+11
A28: 2027 | B28: =B27*(1+$B$40) -> 2.0216663e+08 | C28: =C27*(1+$B$41) -> 0.44398178 | D28: =B28*C28 -> 89758297 | E28: =E27*(1+$B$42) -> 166.36667 | F28: =D28*E28*12 -> 1.7919346e+11
A29: 2028 | B29: =B28*(1+$B$40) -> 2.0727668e+08 | C29: =C28*(1+$B$41) -> 0.44180356 | D29: =B29*C29 -> 91575573 | E29: =E28*(1+$B$42) -> 170.33786 | F29: =D29*E29*12 -> 1.8718545e+11
A30: 2029 | B30: =B29*(1+$B$40) -> 2.1251589e+08 | C30: =C29*(1+$B$41) -> 0.43963602 | D30: =B30*C30 -> 93429642 | E30: =E29*(1+$B$42) -> 174.40385 | F30: =D30*E30*12 -> 1.9553387e+11
A31: 2030 | B31: =B30*(1+$B$40) -> 2.1788754e+08 | C31: =C30*(1+$B$41) -> 0.43747912 | D31: =B31*C31 -> 95321248 | E31: =E30*(1+$B$42) -> 178.56689 | F31: =D31*E31*12 -> 2.0425463e+11
A34: Base Year (Last Actual) | B34: 2024
A35: Industry Subscription | B35: =G7 -> 187580000 | D35: Forecasted Sales Growth | E35: =(F31/F26)^(1/5)-1 -> 0.044599735
A36: GP Market Share (%) | B36: =G11 -> 0.45058109
A37: ARPU (BDT/month) | B37: =G13 -> 155
A38: Forecasted Years | B38: 6
A40: Industry Growth (% p.a.) | B40: =J8 -> 0.025276437
A41: GP Share (pp/yr) | B41: =J12 -> -0.0049061037
A42: ARPU Growth (% p.a.) | B42: =J14 -> 0.023870128

Sheet Bottom-Up Based Sales forecast
B2: Historical | J2: Average YoY Growth Rate
C4: 2019 | D4: 2020 | E4: 2021 | F4: 2022 | G4: 2023 | H4: 2024 | K4: 2020 | L4: 2021 | M4: 2022 | N4: 2023 | O4: 2024
B5: Mobile Communication Revenue | C5: 141546924000 | D5: 137760475000 | E5: 140865753000 | F5: 148179973000 | G5: 156331347000 | H5: 155759617000 | J5: Voice Revenue Growth Rate | K5: =(D7/C7)-1 -> -0.071756244 | L5: =(E7/D7)-1 -> -0.08126228 | M5: =(F7/E7)-1 -> -0.04209342 | N5: =(G7/F7)-1 -> 0.013981792 | O5: =(H7/G7)-1 -> 0.040496753
B6: Mobile Communication Share - Voice | C6: 0.692 | D6: 0.66 | E6: 0.593 | F6: 0.54 | G6: 0.519 | H6: 0.542 | J6: Data Revenue Growth | K6: =(D9/C9)-1 -> 0.13930156 | L6: =(E9/D9)-1 -> 0.022541139 | M6: =(F9/E9)-1 -> 0.090252528 | N6: =(G9/F9)-1 -> 0.1992496 | O6: =(H9/G9)-1 -> -0.041319612
B7: Voice Revenue | C7: =C5*C6 -> 97950471408 | D7: =D5*D6 -> 90921913500 | E7: =E5*E6 -> 83533391529 | F7: =F5*F6 -> 80017185420 | G7: =G5*G6 -> 81135969093 | H7: =H5*H6 -> 84421712414 | J7: Bundle Revenue Growth Rate | K7: - | L7: - | M7: =(F11/E11)-1 -> 0.63765338 | N7: =(G11/F11)-1 -> -0.052801279 | O7: =(H11/G11)-1 -> -0.052259257
B8: Mobile Communication Share - Data | C8: 0.211 | D8: 0.247 | E8: 0.247 | F8: 0.256 | G8: 0.291 | H8: 0.28 | J8: Interconnection Revenue Growth Rate | K8: =(D13/C13)-1 -> -0.23666705 | L8: =(E13/D13)-1 -> -0.028585918 | M8: =(F13/E13)-1 -> -0.031123242 | N8: =(G13/F13)-1 -> 0.14543938 | O8: =(H13/G13)-1 -> -0.003657168
B9: Data Revenue | C9: =C5*C8 -> 29866400964 | D9: =D5*D8 -> 34026837325 | E9: =E5*E8 -> 34793840991 | F9: =F5*F8 -> 37934073088 | G9: =G5*G8 -> 45492421977 | H9: =H5*H8 -> 4.3612693e+10 | J9: Others (Mobile Communicarion) Revenue Growth Rate | K9: =(D15/C15)-1 -> 0.097494133 | L9: =(E15/D15)-1 -> -0.34403021 | M9: =(F15/E15)-1 -> -0.040893428 | N9: =(G15/F15)-1 -> 0.020977378 | O9: =(H15/G15)-1 -> -0.10329145
B10: Mobile Communication Share - Bundle | C10: 0 | D10: 0 | E10: 0.088 | F10: 0.137 | G10: 0.123 | H10: 0.117
B11: Bundle Revenue | C11: =C5*C10 -> 0 | D11: =D5*D10 -> 0 | E11: =E5*E10 -> 12396186264 | F11: =F5*F10 -> 20300656301 | G11: =G5*G10 -> 19228755681 | H11: =H5*H10 -> 18223875189 | J11: Lease Revenues Growth Rate | K11: =(D17/C17)-1 -> 0.020443719 | L11: =(E17/D17)-1 -> 0.10917361 | M11: =(F17/E17)-1 -> 0.032163723 | N11: =(G17/F17)-1 -> 0.1084018 | O11: =(H17/G17)-1 -> 0.12655354
B12: Mobile Communication Share - Interconnection | C12: 0.051 | D12: 0.04 | E12: 0.038 | F12: 0.035 | G12: 0.038 | H12: 0.038
B13: Interconnection Revenue | C13: =C5*C12 -> 7218893124 | D13: =D5*D12 -> 5510419000 | E13: =E5*E12 -> 5352898614 | F13: =F5*F12 -> 5.1862991e+09 | G13: =G5*G12 -> 5940591186 | H13: =H5*H12 -> 5918865446 | J13: Customer Equipment Revenue Growth Rate | K13: =(D19/C19)-1 -> -0.29362129 | L13: =(E19/D19)-1 -> 0.90168642 | M13: =(F19/E19)-1 -> 0.18314831 | N13: =(G19/F19)-1 -> 0.041760443 | O13: =(H19/G19)-1 -> 0.19169271
B14: Mobile Communication Share - Others | C14: 0.047 | D14: 0.053 | E14: 0.034 | F14: 0.031 | G14: 0.03 | H14: 0.027
B15: Others (Mobile Communication) Revenue | C15: =C5*C14 -> 6652705428 | D15: =D5*D14 -> 7301305175 | E15: =E5*E14 -> 4789435602 | F15: =F5*F14 -> 4593579163 | G15: =G5*G14 -> 4689940410 | H15: =H5*H14 -> 4205509659 | J15: Other Revenues Growth Rate | K15: =(D21/C21)-1 -> -0.62398503 | L15: =(E21/D21)-1 -> 0.4420152 | M15: =(F21/E21)-1 -> -0.36973038 | N15: =(G21/F21)-1 -> -0.34998748 | O15: =(H21/G21)-1 -> -0.093307969
B17: Lease Revenues | C17: 1538272000 | D17: 1569720000 | E17: 1741092000 | F17: 1797092000 | G17: 1991900000 | H17: 2243982000
J18: Assumptions
B19: Customer Equipment Revenue | C19: 185351000 | D19: 130928000 | E19: 248984000 | F19: 294585000 | G19: 306887000 | H19: 365715000
J20: Voice Revenue Growth Rate | K20: =AVERAGE(K5:O5) -> -0.02812668
B21: Other Revenues | C21: 385724000 | D21: 145038000 | E21: 209147000 | F21: 131819000 | G21: 85684000 | H21: 77689000 | J21: Data Revenue Growth | K21: =AVERAGE(K6:O6) -> 0.082005044
J22: Bundle Revenue Growth Rate | K22: =AVERAGE(K7:O7) -> 0.17753095
B23: Total Revenue | C23: 143656271000 | D23: 139606161000 | E23: 143065872000 | F23: 150403469000 | G23: 158715818000 | H23: 158447003000 | J23: Interconnection Revenue Growth Rate | K23: =AVERAGE(K8:O8) -> -0.030918799
J24: Others (Mobile Communicarion) Revenue Growth Rate | K24: =AVERAGE(K9:O9) -> -0.073948716
B25: Forecast
J26: Lease Revenues Growth Rate | K26: =AVERAGE(K11:O11) -> 0.079347278
C27: 2025 | D27: 2026 | E27: 2027 | F27: 2028 | G27: 2029 | H27: 2030
B28: Mobile Communication Revenue | C28: =C29+C30+C31+C32+C33 -> 1.6032592e+11 | D28: =D29+D30+D31+D32+D33 -> 1.6523228e+11 | E28: =E29+E30+E31+E32+E33 -> 1.71224e+11 | F28: =F29+F30+F31+F32+F33 -> 1.7844361e+11 | G28: =G29+G30+G31+G32+G33 -> 1.8705725e+11 | H28: =H29+H30+H31+H32+H33 -> 1.9725864e+11 | J28: Customer Equipment Revenue Growth Rate | K28: =AVERAGE(K13:O13) -> 0.20493332
B29: Voice Revenue | C29: =H7*(1+K20) -> 8.204721e+10 | D29: =C29*(1+$K$20) -> 7.9739494e+10 | E29: =D29*(1+$K$20) -> 7.7496687e+10 | F29: =E29*(1+$K$20) -> 7.5316963e+10 | G29: =F29*(1+$K$20) -> 7.3198547e+10 | H29: =G29*(1+$K$20) -> 7.1139715e+10
B30: Data Revenue | C30: =H9*(1+K21) -> 4.7189154e+10 | D30: =C30*(1+$K$21) -> 5.1058902e+10 | E30: =D30*(1+$K$21) -> 5.524599e+10 | F30: =E30*(1+$K$21) -> 5.9776439e+10 | G30: =F30*(1+$K$21) -> 6.4678409e+10 | H30: =G30*(1+$K$21) -> 6.9982365e+10 | J30: Other Revenues Growth Rate | K30: =AVERAGE(K15:O15) -> -0.19899913
B31: Bundle Revenue | C31: =H11*(1+K22) -> 2.1459177e+10 | D31: =C31*(1+$K$22) -> 2.5268845e+10 | E31: =D31*(1+$K$22) -> 2.9754847e+10 | F31: =E31*(1+$K$22) -> 3.5037253e+10 | G31: =F31*(1+$K$22) -> 4.125745e+10 | H31: =G31*(1+$K$22) -> 4.8581924e+10
B32: Interconnection Revenue | C32: =H13*(1+K23) -> 5.7358612e+09 | D32: =C32*(1+$K$23) -> 5.5585153e+09 | E32: =D32*(1+$K$23) -> 5.3866527e+09 | F32: =E32*(1+$K$23) -> 5.2201039e+09 | G32: =F32*(1+$K$23) -> 5.0587045e+09 | H32: =G32*(1+$K$23) -> 4.9022954e+09
B33: Others (Mobile Communication) Revenue | C33: =H15*(1+K24) -> 3.8945176e+09 | D33: =C33*(1+$K$24) -> 3.606523e+09 | E33: =D33*(1+$K$24) -> 3.3398253e+09 | F33: =E33*(1+$K$24) -> 3.0928495e+09 | G33: =F33*(1+$K$24) -> 2.8641372e+09 | H33: =G33*(1+$K$24) -> 2.652338e+09
B35: Lease Revenues | C35: =H17*(1+K26) -> 2.4220359e+09 | D35: =C35*(1+$K$26) -> 2.6142178e+09 | E35: =D35*(1+$K$26) -> 2.8216489e+09 | F35: =E35*(1+$K$26) -> 3.045539e+09 | G35: =F35*(1+$K$26) -> 3.2871943e+09 | H35: =G35*(1+$K$26) -> 3.5480242e+09
B37: Customer Equipment Revenue | C37: =H19*(1+K28) -> 4.4066219e+08 | D37: =C37*(1+$K$28) -> 5.3096855e+08 | E37: =D37*(1+$K$28) -> 6.397817e+08 | F37: =E37*(1+$K$28) -> 7.7089429e+08 | G37: =F37*(1+$K$28) -> 9.2887622e+08 | H37: =G37*(1+$K$28) -> 1.1192339e+09
B39: Other Revenues | C39: =H21*(1+K30) -> 62228956 | D39: =C39*(1+$K$30) -> 49845448 | E39: =D39*(1+$K$30) -> 39926247 | F39: =E39*(1+$K$30) -> 31980959 | G39: =F39*(1+$K$30) -> 25616776 | H39: =G39*(1+$K$30) -> 20519059
B41: Total Revenue | C41: =C28+C35+C37+C39 -> 1.6325085e+11 | D41: =D28+D35+D37+D39 -> 1.6842731e+11 | E41: =E28+E35+E37+E39 -> 1.7472536e+11 | F41: =F28+F35+F37+F39 -> 1.8229202e+11 | G41: =G28+G35+G37+G39 -> 1.9129893e+11 | H41: =H28+H35+H37+H39 -> 2.0194641e+11
B42: Total Revenue (adjusted in 1000s for pro forma) | C42: =C41/1000 -> 1.6325085e+08 | D42: =D41/1000 -> 1.6842731e+08 | E42: =E41/1000 -> 1.7472536e+08 | F42: =F41/1000 -> 1.8229202e+08 | G42: =G41/1000 -> 1.9129893e+08 | H42: =H41/1000 -> 2.0194641e+08
D43: =(D42-C42)/C42 -> 0.031708658 | E43: =(E42-D42)/D42 -> 0.037393264 | F43: =(F42-E42)/E42 -> 0.043306045 | G43: =(G42-F42)/F42 -> 0.049409247 | H43: =(H42-G42)/G42 -> 0.055658854
H44: =AVERAGE(D43:H43) -> 0.043495214

Sheet Assumptions
A1: Pro forma Rate Assumptions
A2: Sales growth | C2: Bottom Up Approach
A3: Current assets/Sales | C3: 0.0529
A4: Current liabilities/Sales | C4: 0.5588
A5: Net fixed assets/Sales | C5: 0.4226
A6: Costs of goods sold/Sales | C6: 0.1397
A7: Depreciation rate | C7: 0.1398
A8: Interest rate on debt | C8: 0.0989
